#VRML_SIM R2020b utf8
# license: Apache License 2.0
# license url: http://www.apache.org/licenses/LICENSE-2.0
# This is a proto file for Webots for the Pointone
# Extracted from: robot2.urdf

PROTO Pointone [
  field  SFVec3f     translation     0 0 0
  field  SFRotation  rotation        0 1 0 0
  field  SFString    controller      "void" # Is `Robot.controller`.
  field  MFString    controllerArgs  []     # Is `Robot.controllerArgs`.
  field  SFString    customData      ""     # Is `Robot.customData`.
  field  SFBool      supervisor      FALSE  # Is `Robot.supervisor`.
  field  SFBool      synchronization TRUE   # Is `Robot.synchronization`.
  field  SFBool      selfCollision   FALSE  # Is `Robot.selfCollision`.
]
{
  Robot {
    translation IS translation
    rotation IS rotation
    controller IS controller
    controllerArgs IS controllerArgs
    customData IS customData
    supervisor IS supervisor
    synchronization IS synchronization
    selfCollision IS selfCollision
    children [
      Shape {
        appearance PBRAppearance {
          baseColor 0.300000 0.300000 0.500000
          transparency 0.000000
          roughness 1.000000
          metalness 0
          emissiveColor 0.000000 0.000000 0.000000
        }
        geometry DEF hip2 IndexedFaceSet {
          coord Coordinate {
            point [
              0.299999 -0.139999 0.049999, 0.299999 0.139999 0.020000, 0.299999 0.139999 0.049999, 0.299999 -0.139999 0.020000, -0.299999 0.139999 0.049999, -0.299999 -0.139999 0.049999, -0.299999 -0.139999 0.020000, -0.007360 -0.089999 0.020000, -0.007360 -0.139999 0.020000, -0.007360 0.089999 0.020000, -0.299999 0.139999 0.020000, -0.007360 0.139999 0.020000, 0.050469 0.089999 0.020000, 0.050469 -0.089999 0.020000, 0.050469 -0.139999 0.020000, 0.050469 0.139999 0.020000, 0.037360 0.139999 -0.038042, 0.065000 0.139999 0.000000, -0.007360 0.139999 -0.023511, -0.007360 -0.139999 -0.023511, 0.037360 -0.139999 -0.038042, 0.065000 -0.139999 0.000000, -0.007360 0.089999 -0.023511, 0.037360 0.089999 -0.038042, 0.065000 0.089999 0.000000, 0.037360 -0.089999 -0.038042, -0.007360 -0.089999 -0.023511, 0.065000 -0.089999 0.000000, 
            ]
          }
          coordIndex [
            1 0 3 -1 4 0 2 -1 0 4 5 -1 6 7 8 -1 7 6 9 -1 10 9 6 -1 9 10 11 -1 7 12 13 -1 12 7 9 -1 13 3 14 -1 3 13 1 -1 12 1 13 -1 1 12 15 -1 6 4 10 -1 4 6 5 -1 16 15 17 -1 18 15 16 -1 15 18 11 -1 15 2 1 -1 11 2 15 -1 2 11 4 -1 4 11 10 -1 19 14 8 -1 14 19 20 -1 14 20 21 -1 8 5 6 -1 5 8 0 -1 14 0 8 -1 0 14 3 -1 22 16 23 -1 16 22 18 -1 12 17 15 -1 17 12 24 -1 22 11 18 -1 11 22 9 -1 22 12 9 -1 12 22 23 -1 12 23 24 -1 24 16 17 -1 16 24 23 -1 19 25 20 -1 25 19 26 -1 21 25 27 -1 25 21 20 -1 19 7 26 -1 7 19 8 -1 25 13 27 -1 26 13 25 -1 13 26 7 -1 14 27 13 -1 27 14 21 -1 
          ]
          creaseAngle 1
        }
      }
      HingeJoint {
        jointParameters HingeJointParameters {
          axis 0.000000 1.000000 0.000000
          anchor 0.000000 0.000000 0.000000
          dampingConstant 0.0
          staticFriction 0.0
        }
        device [
          RotationalMotor {
            name "hip2rightthigh"
          }
          PositionSensor {
            name "hip2rightthigh_sensor"
          }
        ]
        endPoint Solid {
          translation 0.000000 0.000000 0.000000
          rotation 1.000000 0.000000 0.000000 0.000000
          children [
            Transform {
              translation 0.025000 -0.140000 0.000000
              rotation 0.000000 1.000000 0.000000 0.000000
              children [
                Shape {
                  appearance PBRAppearance {
                    baseColor 0.300000 0.300000 0.500000
                    transparency 0.000000
                    roughness 1.000000
                    metalness 0
                    emissiveColor 0.000000 0.000000 0.000000
                  }
                  geometry DEF rightthigh2 IndexedFaceSet {
                    coord Coordinate {
                      point [
                        -0.015450 0.000000 0.047552, 0.040450 -0.049999 0.029388, 0.040450 0.000000 0.029388, -0.015450 -0.049999 0.047552, 0.025000 -0.049999 -0.034409, 0.040450 0.000000 -0.029388, 0.040450 -0.049999 -0.029388, 0.025000 0.000000 -0.034409, -0.025000 -0.049999 -0.034409, -0.049999 0.000000 0.000000, -0.025000 0.000000 -0.034409, -0.049999 -0.049999 0.000000, 0.025000 -0.049999 -0.265590, -0.025000 -0.049999 -0.265590, -0.015450 -0.049999 -0.347552, -0.049999 -0.049999 -0.299999, 0.040450 -0.049999 -0.329389, 0.040450 -0.049999 -0.270610, 0.025000 0.000000 -0.265590, -0.025000 0.000000 -0.265590, 0.040450 0.000000 -0.329389, 0.040450 0.000000 -0.270610, -0.015450 0.000000 -0.347552, -0.049999 0.000000 -0.299999, 
                      ]
                    }
                    coordIndex [
                      1 0 3 -1 4 5 6 -1 5 4 7 -1 8 9 10 -1 9 8 11 -1 1 5 2 -1 5 1 6 -1 8 3 11 -1 4 3 8 -1 1 4 6 -1 3 4 1 -1 8 12 4 -1 13 12 8 -1 14 12 13 -1 14 13 15 -1 12 16 17 -1 12 14 16 -1 11 0 9 -1 0 11 3 -1 7 0 2 -1 7 2 5 -1 0 7 10 -1 0 10 9 -1 18 10 7 -1 18 19 10 -1 20 18 21 -1 22 18 20 -1 18 22 19 -1 19 22 23 -1 13 10 19 -1 10 13 8 -1 4 18 7 -1 18 4 12 -1 18 17 21 -1 17 18 12 -1 14 20 16 -1 20 14 22 -1 14 23 22 -1 23 14 15 -1 17 20 21 -1 20 17 16 -1 15 19 23 -1 19 15 13 -1 
                    ]
                    creaseAngle 1
                  }
                }
              ]
            }
            HingeJoint {
              jointParameters HingeJointParameters {
                axis 0.000000 1.000000 0.000000
                anchor 0.000000 0.000000 0.000000
                dampingConstant 0.0
                staticFriction 0.0
              }
              device [
                RotationalMotor {
                  name "rightthigh2rightfemur"
                }
                PositionSensor {
                  name "rightthigh2rightfemur_sensor"
                }
              ]
              endPoint Solid {
                translation 0.000000 0.000000 0.000000
                rotation 1.000000 0.000000 0.000000 0.000000
                children [
                  Transform {
                    translation 0.030000 -0.190000 -0.300000
                    rotation 0.000000 1.000000 0.000000 0.000000
                    children [
                      Shape {
                        appearance PBRAppearance {
                          baseColor 0.300000 0.300000 0.500000
                          transparency 0.000000
                          roughness 1.000000
                          metalness 0
                          emissiveColor 0.000000 0.000000 0.000000
                        }
                        geometry DEF rightfemur2 IndexedFaceSet {
                          coord Coordinate {
                            point [
                              -0.015450 0.000000 0.047552, 0.040450 -0.049999 0.029388, 0.040450 0.000000 0.029388, -0.015450 -0.049999 0.047552, 0.025000 -0.049999 -0.034409, 0.040450 0.000000 -0.029388, 0.040450 -0.049999 -0.029388, 0.025000 0.000000 -0.034409, -0.025000 -0.049999 -0.034409, -0.049999 0.000000 0.000000, -0.025000 0.000000 -0.034409, -0.049999 -0.049999 0.000000, 0.025000 -0.049999 -0.265590, -0.025000 -0.049999 -0.265590, -0.015450 -0.049999 -0.347552, -0.049999 -0.049999 -0.299999, 0.040450 -0.049999 -0.329389, 0.040450 -0.049999 -0.270610, 0.025000 0.000000 -0.265590, -0.025000 0.000000 -0.265590, 0.040450 0.000000 -0.329389, 0.040450 0.000000 -0.270610, -0.015450 0.000000 -0.347552, -0.049999 0.000000 -0.299999, 
                            ]
                          }
                          coordIndex [
                            1 0 3 -1 4 5 6 -1 5 4 7 -1 8 9 10 -1 9 8 11 -1 1 5 2 -1 5 1 6 -1 8 3 11 -1 4 3 8 -1 1 4 6 -1 3 4 1 -1 8 12 4 -1 13 12 8 -1 14 12 13 -1 14 13 15 -1 12 16 17 -1 12 14 16 -1 11 0 9 -1 0 11 3 -1 7 0 2 -1 7 2 5 -1 0 7 10 -1 0 10 9 -1 18 10 7 -1 18 19 10 -1 20 18 21 -1 22 18 20 -1 18 22 19 -1 19 22 23 -1 13 10 19 -1 10 13 8 -1 4 18 7 -1 18 4 12 -1 18 17 21 -1 17 18 12 -1 14 20 16 -1 20 14 22 -1 14 23 22 -1 23 14 15 -1 17 20 21 -1 20 17 16 -1 15 19 23 -1 19 15 13 -1 
                          ]
                          creaseAngle 1
                        }
                      }
                    ]
                  }
                  Solid {
                    translation 0.000000 0.000000 0.000000
                    rotation 1.000000 0.000000 0.000000 0.000000
                    children [
                      Transform {
                        translation 0.025000 -0.240000 -0.610000
                        rotation 0.000000 1.000000 0.000000 0.000000
                        children [
                          Shape {
                            appearance PBRAppearance {
                              baseColor 0.300000 0.300000 0.500000
                              transparency 0.000000
                              roughness 1.000000
                              metalness 0
                              emissiveColor 0.000000 0.000000 0.000000
                            }
                            geometry DEF rightfoot2 IndexedFaceSet {
                              coord Coordinate {
                                point [
                                  -0.040450 0.000000 0.029388, 0.015450 -0.049999 0.047552, 0.015450 0.000000 0.047552, -0.040450 -0.049999 0.029388, 0.049999 0.000000 0.000000, 0.049999 -0.049999 0.000000, -0.040450 -0.049999 0.000000, -0.040450 0.000000 0.000000, -0.049999 -0.049999 -0.030000, -0.049999 -0.049999 0.000000, 0.049999 -0.049999 -0.030000, 0.174999 0.000000 -0.049999, 0.049999 0.000000 -0.030000, 0.174999 0.000000 -0.030000, -0.049999 0.000000 -0.030000, -0.174999 0.000000 -0.049999, -0.174999 0.000000 -0.030000, -0.049999 0.000000 0.000000, 0.174999 -0.250000 -0.030000, 0.174999 -0.250000 -0.049999, -0.174999 -0.250000 -0.049999, -0.174999 -0.250000 -0.030000, 
                                ]
                              }
                              coordIndex [
                                1 0 3 -1 1 4 2 -1 4 1 5 -1 6 0 7 -1 0 6 3 -1 8 6 9 -1 10 6 8 -1 6 10 5 -1 6 1 3 -1 1 6 5 -1 11 12 13 -1 12 11 14 -1 15 14 11 -1 14 15 16 -1 7 2 4 -1 2 7 0 -1 12 7 4 -1 14 7 12 -1 7 14 17 -1 18 11 13 -1 11 18 19 -1 20 18 21 -1 18 20 19 -1 20 16 15 -1 16 20 21 -1 14 16 8 -1 10 13 12 -1 13 10 18 -1 8 18 10 -1 21 8 16 -1 8 21 18 -1 20 11 19 -1 11 20 15 -1 5 12 4 -1 12 5 10 -1 8 17 14 -1 17 8 9 -1 17 6 7 -1 6 17 9 -1 
                              ]
                              creaseAngle 1
                            }
                          }
                        ]
                      }
                    ]
                    name "rightfoot"
                    boundingObject Transform {
                      translation 0.025000 -0.240000 -0.610000
                      rotation 0.000000 1.000000 0.000000 0.000000
                      children [
                        USE rightfoot2
                      ]
                    }
                    physics Physics {
                      density -1
                      mass 4.000000
                      centerOfMass [ 0.000000 0.000000 0.000000 ]
                    }
                  }
                ]
                name "rightfemur"
                boundingObject Transform {
                  translation 0.030000 -0.190000 -0.300000
                  rotation 0.000000 1.000000 0.000000 0.000000
                  children [
                    USE rightfemur2
                  ]
                }
                physics Physics {
                  density -1
                  mass 4.000000
                  centerOfMass [ 0.000000 0.000000 0.000000 ]
                }
              }
            }
          ]
          name "rightthigh"
          boundingObject Transform {
            translation 0.025000 -0.140000 0.000000
            rotation 0.000000 1.000000 0.000000 0.000000
            children [
              USE rightthigh2
            ]
          }
          physics Physics {
            density -1
            mass 4.000000
            centerOfMass [ 0.000000 0.000000 0.000000 ]
          }
        }
      }
      HingeJoint {
        jointParameters HingeJointParameters {
          axis 0.000000 1.000000 0.000000
          anchor 0.000000 0.000000 0.000000
          dampingConstant 0.0
          staticFriction 0.0
        }
        device [
          RotationalMotor {
            name "hip2leftthigh"
          }
          PositionSensor {
            name "hip2leftthigh_sensor"
          }
        ]
        endPoint Solid {
          translation 0.000000 0.000000 0.000000
          rotation 1.000000 0.000000 0.000000 0.000000
          children [
            Transform {
              translation 0.025000 0.140000 0.000000
              rotation 0.000000 1.000000 0.000000 0.000000
              children [
                Shape {
                  appearance PBRAppearance {
                    baseColor 0.300000 0.300000 0.500000
                    transparency 0.000000
                    roughness 1.000000
                    metalness 0
                    emissiveColor 0.000000 0.000000 0.000000
                  }
                  geometry DEF leftthigh2 IndexedFaceSet {
                    coord Coordinate {
                      point [
                        -0.040450 0.049999 0.029388, 0.015450 0.000000 0.047552, 0.015450 0.049999 0.047552, -0.040450 0.000000 0.029388, -0.040450 0.000000 -0.029388, -0.025000 0.049999 -0.034409, -0.025000 0.000000 -0.034409, -0.040450 0.049999 -0.029388, 0.049999 0.000000 0.000000, 0.025000 0.049999 -0.034409, 0.049999 0.049999 0.000000, 0.025000 0.000000 -0.034409, -0.025000 0.049999 -0.265590, 0.025000 0.049999 -0.265590, 0.015450 0.049999 -0.347552, 0.049999 0.049999 -0.299999, -0.040450 0.049999 -0.329389, -0.040450 0.049999 -0.270610, -0.025000 0.000000 -0.265590, 0.025000 0.000000 -0.265590, -0.040450 0.000000 -0.329389, -0.040450 0.000000 -0.270610, 0.015450 0.000000 -0.347552, 0.049999 0.000000 -0.299999, 
                      ]
                    }
                    coordIndex [
                      1 0 3 -1 4 5 6 -1 5 4 7 -1 8 9 10 -1 9 8 11 -1 4 0 7 -1 0 4 3 -1 9 2 10 -1 5 2 9 -1 0 5 7 -1 2 5 0 -1 9 12 5 -1 13 12 9 -1 14 12 13 -1 14 13 15 -1 12 16 17 -1 12 14 16 -1 1 10 2 -1 10 1 8 -1 6 1 3 -1 6 3 4 -1 1 6 11 -1 1 11 8 -1 18 11 6 -1 18 19 11 -1 20 18 21 -1 22 18 20 -1 18 22 19 -1 19 22 23 -1 11 13 9 -1 13 11 19 -1 18 5 12 -1 5 18 6 -1 17 18 12 -1 18 17 21 -1 20 14 22 -1 14 20 16 -1 23 14 15 -1 14 23 22 -1 20 17 16 -1 17 20 21 -1 19 15 13 -1 15 19 23 -1 
                    ]
                    creaseAngle 1
                  }
                }
              ]
            }
            HingeJoint {
              jointParameters HingeJointParameters {
                axis 0.000000 1.000000 0.000000
                anchor 0.000000 0.000000 0.000000
                dampingConstant 0.0
                staticFriction 0.0
              }
              device [
                RotationalMotor {
                  name "leftthigh2leftfemur"
                }
                PositionSensor {
                  name "leftthigh2leftfemur_sensor"
                }
              ]
              endPoint Solid {
                translation 0.000000 0.000000 0.000000
                rotation 1.000000 0.000000 0.000000 0.000000
                children [
                  Transform {
                    translation 0.030000 0.190000 -0.300000
                    rotation 0.000000 1.000000 0.000000 0.000000
                    children [
                      Shape {
                        appearance PBRAppearance {
                          baseColor 0.300000 0.300000 0.500000
                          transparency 0.000000
                          roughness 1.000000
                          metalness 0
                          emissiveColor 0.000000 0.000000 0.000000
                        }
                        geometry DEF leftfemur2 IndexedFaceSet {
                          coord Coordinate {
                            point [
                              -0.040450 0.049999 0.029388, 0.015450 0.000000 0.047552, 0.015450 0.049999 0.047552, -0.040450 0.000000 0.029388, -0.040450 0.000000 -0.029388, -0.025000 0.049999 -0.034409, -0.025000 0.000000 -0.034409, -0.040450 0.049999 -0.029388, 0.049999 0.000000 0.000000, 0.025000 0.049999 -0.034409, 0.049999 0.049999 0.000000, 0.025000 0.000000 -0.034409, -0.025000 0.049999 -0.265590, 0.025000 0.049999 -0.265590, 0.015450 0.049999 -0.347552, 0.049999 0.049999 -0.299999, -0.040450 0.049999 -0.329389, -0.040450 0.049999 -0.270610, -0.025000 0.000000 -0.265590, 0.025000 0.000000 -0.265590, -0.040450 0.000000 -0.329389, -0.040450 0.000000 -0.270610, 0.015450 0.000000 -0.347552, 0.049999 0.000000 -0.299999, 
                            ]
                          }
                          coordIndex [
                            1 0 3 -1 4 5 6 -1 5 4 7 -1 8 9 10 -1 9 8 11 -1 4 0 7 -1 0 4 3 -1 9 2 10 -1 5 2 9 -1 0 5 7 -1 2 5 0 -1 9 12 5 -1 13 12 9 -1 14 12 13 -1 14 13 15 -1 12 16 17 -1 12 14 16 -1 1 10 2 -1 10 1 8 -1 6 1 3 -1 6 3 4 -1 1 6 11 -1 1 11 8 -1 18 11 6 -1 18 19 11 -1 20 18 21 -1 22 18 20 -1 18 22 19 -1 19 22 23 -1 11 13 9 -1 13 11 19 -1 18 5 12 -1 5 18 6 -1 17 18 12 -1 18 17 21 -1 20 14 22 -1 14 20 16 -1 23 14 15 -1 14 23 22 -1 20 17 16 -1 17 20 21 -1 19 15 13 -1 15 19 23 -1 
                          ]
                          creaseAngle 1
                        }
                      }
                    ]
                  }
                  Solid {
                    translation 0.000000 0.000000 0.000000
                    rotation 1.000000 0.000000 0.000000 0.000000
                    children [
                      Transform {
                        translation 0.025000 0.240000 -0.610000
                        rotation 0.000000 1.000000 0.000000 0.000000
                        children [
                          Shape {
                            appearance PBRAppearance {
                              baseColor 0.300000 0.300000 0.500000
                              transparency 0.000000
                              roughness 1.000000
                              metalness 0
                              emissiveColor 0.000000 0.000000 0.000000
                            }
                            geometry DEF leftfoot2 IndexedFaceSet {
                              coord Coordinate {
                                point [
                                  -0.015450 0.049999 0.047552, 0.040450 0.000000 0.029388, 0.040450 0.049999 0.029388, -0.015450 0.000000 0.047552, -0.049999 0.000000 0.000000, -0.049999 0.049999 0.000000, 0.040450 0.049999 0.000000, 0.040450 0.000000 0.000000, 0.049999 0.049999 -0.030000, 0.049999 0.049999 0.000000, -0.049999 0.049999 -0.030000, -0.174999 0.000000 -0.049999, -0.049999 0.000000 -0.030000, -0.174999 0.000000 -0.030000, 0.049999 0.000000 -0.030000, 0.174999 0.000000 -0.049999, 0.174999 0.000000 -0.030000, 0.049999 0.000000 0.000000, -0.174999 0.250000 -0.030000, -0.174999 0.250000 -0.049999, 0.174999 0.250000 -0.049999, 0.174999 0.250000 -0.030000, 
                                ]
                              }
                              coordIndex [
                                1 0 3 -1 4 0 5 -1 0 4 3 -1 1 6 2 -1 6 1 7 -1 8 6 9 -1 10 6 8 -1 6 10 5 -1 6 0 2 -1 0 6 5 -1 11 12 13 -1 12 11 14 -1 15 14 11 -1 14 15 16 -1 7 3 4 -1 3 7 1 -1 12 7 4 -1 14 7 12 -1 7 14 17 -1 11 18 19 -1 18 11 13 -1 20 18 21 -1 18 20 19 -1 16 20 21 -1 20 16 15 -1 21 8 16 -1 21 10 8 -1 18 10 21 -1 13 10 18 -1 10 13 12 -1 16 8 14 -1 11 20 15 -1 20 11 19 -1 12 5 10 -1 5 12 4 -1 17 8 9 -1 8 17 14 -1 6 17 9 -1 17 6 7 -1 
                              ]
                              creaseAngle 1
                            }
                          }
                        ]
                      }
                    ]
                    name "leftfoot"
                    boundingObject Transform {
                      translation 0.025000 0.240000 -0.610000
                      rotation 0.000000 1.000000 0.000000 0.000000
                      children [
                        USE leftfoot2
                      ]
                    }
                    physics Physics {
                      density -1
                      mass 4.000000
                      centerOfMass [ 0.000000 0.000000 0.000000 ]
                    }
                  }
                ]
                name "leftfemur"
                boundingObject Transform {
                  translation 0.030000 0.190000 -0.300000
                  rotation 0.000000 1.000000 0.000000 0.000000
                  children [
                    USE leftfemur2
                  ]
                }
                physics Physics {
                  density -1
                  mass 4.000000
                  centerOfMass [ 0.000000 0.000000 0.000000 ]
                }
              }
            }
          ]
          name "leftthigh"
          boundingObject Transform {
            translation 0.025000 0.140000 0.000000
            rotation 0.000000 1.000000 0.000000 0.000000
            children [
              USE leftthigh2
            ]
          }
          physics Physics {
            density -1
            mass 4.000000
            centerOfMass [ 0.000000 0.000000 0.000000 ]
          }
        }
      }
    ]
    name "hip"
    boundingObject USE hip2
    physics Physics {
      density -1
      mass 4.000000
      centerOfMass [ 0.000000 0.000000 0.000000 ]
    }
  }
}
