#VRML_SIM R2020b utf8
# license: Apache License 2.0
# license url: http://www.apache.org/licenses/LICENSE-2.0
# This is a proto file for Webots for the Pointone
# Extracted from: robot.urdf

PROTO Pointone [
  field  SFVec3f     translation     0 0 0
  field  SFRotation  rotation        0 1 0 0
  field  SFString    controller      "void" # Is `Robot.controller`.
  field  MFString    controllerArgs  []     # Is `Robot.controllerArgs`.
  field  SFString    customData      ""     # Is `Robot.customData`.
  field  SFBool      supervisor      FALSE  # Is `Robot.supervisor`.
  field  SFBool      synchronization TRUE   # Is `Robot.synchronization`.
  field  SFBool      selfCollision   FALSE  # Is `Robot.selfCollision`.
]
{
  Robot {
    translation IS translation
    rotation IS rotation
    controller IS controller
    controllerArgs IS controllerArgs
    customData IS customData
    supervisor IS supervisor
    synchronization IS synchronization
    selfCollision IS selfCollision
    children [
      Shape {
        appearance PBRAppearance {
          baseColor 1.000000 1.000000 0.000000
          transparency 0.000000
          roughness 1.000000
          metalness 0
          emissiveColor 0.000000 0.000000 0.000000
        }
        geometry DEF bit12 IndexedFaceSet {
          coord Coordinate {
            point [
              0.000000 0.100000 1.000000, 0.100000 0.000000 1.000000, 0.100000 0.100000 1.000000, 0.000000 0.000000 1.000000, 0.000000 0.000000 0.000000, 0.100000 0.100000 0.000000, 0.100000 0.000000 0.000000, 0.000000 0.100000 0.000000, 
            ]
          }
          coordIndex [
            1 0 3 -1 4 5 6 -1 5 4 7 -1 4 1 3 -1 1 4 6 -1 1 5 2 -1 5 1 6 -1 5 0 2 -1 0 5 7 -1 4 0 7 -1 0 4 3 -1 
          ]
          creaseAngle 1
        }
      }
      HingeJoint {
        jointParameters HingeJointParameters {
          axis 1.000000 0.000000 0.000000
          anchor 0.000000 0.000000 0.200000
          dampingConstant 0.0
          staticFriction 0.0
        }
        device [
          RotationalMotor {
            name "bit12bitb"
          }
          PositionSensor {
            name "bit12bitb_sensor"
          }
        ]
        endPoint Solid {
          translation 0.000000 0.000000 0.200000
          rotation 1.000000 0.000000 0.000000 0.000000
          children [
            Transform {
              translation 0.000000 0.000000 1.200000
              rotation 0.000000 1.000000 0.000000 0.000000
              children [
                Shape {
                  appearance PBRAppearance {
                    baseColor 1.000000 1.000000 0.000000
                    transparency 0.000000
                    roughness 1.000000
                    metalness 0
                    emissiveColor 0.000000 0.000000 0.000000
                  }
                  geometry DEF bitb2 IndexedFaceSet {
                    coord Coordinate {
                      point [
                        0.000000 0.100000 1.000000, 0.100000 0.000000 1.000000, 0.100000 0.100000 1.000000, 0.000000 0.000000 1.000000, 0.000000 0.000000 0.000000, 0.100000 0.100000 0.000000, 0.100000 0.000000 0.000000, 0.000000 0.100000 0.000000, 
                      ]
                    }
                    coordIndex [
                      1 0 3 -1 4 5 6 -1 5 4 7 -1 4 1 3 -1 1 4 6 -1 1 5 2 -1 5 1 6 -1 5 0 2 -1 0 5 7 -1 4 0 7 -1 0 4 3 -1 
                    ]
                    creaseAngle 1
                  }
                }
              ]
            }
          ]
          name "bitb"
          boundingObject Transform {
            translation 0.000000 0.000000 1.200000
            rotation 0.000000 1.000000 0.000000 0.000000
            children [
              USE bitb2
            ]
          }
          physics Physics {
            density -1
            mass 0.010000
            centerOfMass [ 0.050000 0.050000 0.500000 ]
          }
        }
      }
    ]
    name "bit1"
    boundingObject USE bit12
    physics Physics {
      density -1
      mass 0.010000
      centerOfMass [ 0.050000 0.050000 0.500000 ]
    }
  }
}
