#VRML_SIM R2020b utf8
# license: Apache License 2.0
# license url: http://www.apache.org/licenses/LICENSE-2.0
# This is a proto file for Webots for the Pointone
# Extracted from: robot.urdf

PROTO Pointone [
  field  SFVec3f     translation     0 0 0
  field  SFRotation  rotation        0 1 0 0
  field  SFString    controller      "void" # Is `Robot.controller`.
  field  MFString    controllerArgs  []     # Is `Robot.controllerArgs`.
  field  SFString    customData      ""     # Is `Robot.customData`.
  field  SFBool      supervisor      FALSE  # Is `Robot.supervisor`.
  field  SFBool      synchronization TRUE   # Is `Robot.synchronization`.
  field  SFBool      selfCollision   FALSE  # Is `Robot.selfCollision`.
]
{
  Robot {
    translation IS translation
    rotation IS rotation
    controller IS controller
    controllerArgs IS controllerArgs
    customData IS customData
    supervisor IS supervisor
    synchronization IS synchronization
    selfCollision IS selfCollision
    children [
      Transform {
        translation 0.000000 -0.010000 0.000000
        rotation 0.000000 1.000000 0.000000 0.000000
        children [
          Shape {
            appearance PBRAppearance {
              baseColor 1.000000 0.000000 0.000000
              transparency 0.000000
              roughness 1.000000
              metalness 0
              emissiveColor 0.000000 0.000000 0.000000
            }
            geometry DEF hip2 IndexedFaceSet {
              coord Coordinate {
                point [
                  -0.007360 0.150000 0.576488, 0.037360 0.200000 0.561957, 0.037360 0.150000 0.561957, -0.007360 0.200000 0.576488, -0.007360 0.200000 0.623511, 0.037360 0.169999 0.638041, 0.037360 0.200000 0.638041, -0.007360 0.169999 0.623511, 0.050468 0.169999 0.620000, 0.065000 0.200000 0.599999, 0.065000 0.150000 0.599999, 0.050468 0.150000 0.620000, -0.007360 0.169999 0.620000, -0.007360 0.150000 0.620000, -0.007360 -0.129999 0.576488, 0.037360 -0.080000 0.561957, 0.037360 -0.129999 0.561957, -0.007360 -0.080000 0.576488, -0.007360 -0.110000 0.623511, 0.037360 -0.129999 0.638041, 0.037360 -0.110000 0.638041, -0.007360 -0.129999 0.623511, 0.050468 -0.110000 0.620000, 0.065000 -0.080000 0.599999, 0.050468 -0.080000 0.620000, 0.065000 -0.129999 0.599999, -0.007360 -0.110000 0.620000, -0.007360 -0.080000 0.620000, 0.299999 -0.110000 0.650000, 0.299999 0.169999 0.620000, 0.299999 0.169999 0.650000, 0.299999 -0.110000 0.620000, -0.299999 0.169999 0.650000, -0.299999 -0.110000 0.650000, -0.299999 -0.110000 0.620000, -0.299999 0.169999 0.620000, 
                ]
              }
              coordIndex [
                1 0 3 -1 4 5 6 -1 5 4 7 -1 8 6 5 -1 6 8 9 -1 10 8 11 -1 8 10 9 -1 3 12 4 -1 0 12 3 -1 12 0 13 -1 4 12 7 -1 0 11 13 -1 11 0 2 -1 11 2 10 -1 9 4 6 -1 9 3 4 -1 3 9 1 -1 10 1 9 -1 1 10 2 -1 14 15 16 -1 15 14 17 -1 18 19 20 -1 19 18 21 -1 20 19 22 -1 22 23 24 -1 22 25 23 -1 25 22 19 -1 17 26 27 -1 14 26 17 -1 21 26 14 -1 26 21 18 -1 21 25 19 -1 14 25 21 -1 25 14 16 -1 15 24 23 -1 17 24 15 -1 24 17 27 -1 25 15 23 -1 15 25 16 -1 28 29 30 -1 29 28 31 -1 32 28 30 -1 28 32 33 -1 34 27 26 -1 35 27 34 -1 27 35 13 -1 13 35 12 -1 27 11 24 -1 11 27 13 -1 24 31 22 -1 31 24 29 -1 11 29 24 -1 29 11 8 -1 34 32 35 -1 32 34 33 -1 30 5 32 -1 8 30 29 -1 30 8 5 -1 7 32 5 -1 35 7 12 -1 7 35 32 -1 33 20 28 -1 33 18 20 -1 34 18 33 -1 18 34 26 -1 22 28 20 -1 28 22 31 -1 
              ]
              creaseAngle 1
            }
          }
        ]
      }
      HingeJoint {
        jointParameters HingeJointParameters {
          axis 1.000000 0.000000 0.000000
          anchor 0.000000 0.000000 0.000000
          dampingConstant 0.0
          staticFriction 0.0
        }
        device [
          RotationalMotor {
            name "hip2rightthigh"
          }
          PositionSensor {
            name "hip2rightthigh_sensor"
          }
        ]
        endPoint Solid {
          translation 0.000000 0.000000 0.000000
          rotation 1.000000 0.000000 0.000000 0.000000
          children [
            Transform {
              translation 0.000000 -0.190000 0.300000
              rotation 0.000000 1.000000 0.000000 0.000000
              children [
                Shape {
                  appearance PBRAppearance {
                    baseColor 1.000000 0.000000 0.000000
                    transparency 0.000000
                    roughness 1.000000
                    metalness 0
                    emissiveColor 0.000000 0.000000 0.000000
                  }
                  geometry DEF rightthigh2 IndexedFaceSet {
                    coord Coordinate {
                      point [
                        0.049999 0.000000 0.265590, 0.049999 0.049999 0.034409, 0.049999 0.049999 0.265590, 0.049999 0.000000 0.034409, 0.000000 0.000000 0.034409, 0.000000 0.049999 0.265590, 0.000000 0.049999 0.034409, 0.000000 0.000000 0.265590, 0.040450 0.049999 0.347552, 0.075000 0.049999 0.299999, -0.015450 0.049999 0.329389, -0.015450 0.049999 0.270610, 0.040450 0.049999 -0.047552, 0.075000 0.049999 0.000000, -0.015450 0.049999 -0.029388, -0.015450 0.049999 0.029388, 0.040450 0.000000 0.347552, -0.015450 0.000000 0.329389, -0.015450 0.000000 0.270610, 0.075000 0.000000 0.299999, -0.015450 0.000000 -0.029388, -0.015450 0.000000 0.029388, 0.040450 0.000000 -0.047552, 0.075000 0.000000 0.000000, 
                      ]
                    }
                    coordIndex [
                      1 0 3 -1 4 5 6 -1 5 4 7 -1 2 8 9 -1 5 8 2 -1 8 5 10 -1 10 5 11 -1 1 5 2 -1 1 6 5 -1 12 6 1 -1 12 1 13 -1 6 14 15 -1 6 12 14 -1 7 16 17 -1 7 17 18 -1 16 7 0 -1 16 0 19 -1 7 3 0 -1 4 3 7 -1 20 4 21 -1 22 4 20 -1 4 22 3 -1 3 22 23 -1 20 12 22 -1 12 20 14 -1 3 13 1 -1 13 3 23 -1 20 15 14 -1 15 20 21 -1 15 4 6 -1 4 15 21 -1 23 12 13 -1 12 23 22 -1 18 5 7 -1 5 18 11 -1 16 9 8 -1 9 16 19 -1 18 10 11 -1 10 18 17 -1 19 2 9 -1 2 19 0 -1 10 16 8 -1 16 10 17 -1 
                    ]
                    creaseAngle 1
                  }
                }
              ]
            }
            HingeJoint {
              jointParameters HingeJointParameters {
                axis 1.000000 0.000000 0.000000
                anchor 0.000000 0.000000 0.000000
                dampingConstant 0.0
                staticFriction 0.0
              }
              device [
                RotationalMotor {
                  name "rightthigh2rightfemur"
                }
                PositionSensor {
                  name "rightthigh2rightfemur_sensor"
                }
              ]
              endPoint Solid {
                translation 0.000000 0.000000 0.000000
                rotation 1.000000 0.000000 0.000000 0.000000
                children [
                  Transform {
                    translation 0.000000 -0.240000 0.000000
                    rotation 0.000000 1.000000 0.000000 0.000000
                    children [
                      Shape {
                        appearance PBRAppearance {
                          baseColor 1.000000 0.000000 0.000000
                          transparency 0.000000
                          roughness 1.000000
                          metalness 0
                          emissiveColor 0.000000 0.000000 0.000000
                        }
                        geometry DEF rightfemur2 IndexedFaceSet {
                          coord Coordinate {
                            point [
                              0.049999 0.000000 0.265590, 0.049999 0.049999 0.034409, 0.049999 0.049999 0.265590, 0.049999 0.000000 0.034409, 0.000000 0.000000 0.034409, 0.000000 0.049999 0.265590, 0.000000 0.049999 0.034409, 0.000000 0.000000 0.265590, 0.040450 0.049999 0.347552, 0.075000 0.049999 0.299999, -0.015450 0.049999 0.329389, -0.015450 0.049999 0.270610, 0.040450 0.049999 -0.047552, 0.075000 0.049999 0.000000, -0.015450 0.049999 -0.029388, -0.015450 0.049999 0.029388, 0.040450 0.000000 0.347552, -0.015450 0.000000 0.329389, -0.015450 0.000000 0.270610, 0.075000 0.000000 0.299999, -0.015450 0.000000 -0.029388, -0.015450 0.000000 0.029388, 0.040450 0.000000 -0.047552, 0.075000 0.000000 0.000000, 
                            ]
                          }
                          coordIndex [
                            1 0 3 -1 4 5 6 -1 5 4 7 -1 2 8 9 -1 5 8 2 -1 8 5 10 -1 10 5 11 -1 1 5 2 -1 1 6 5 -1 12 6 1 -1 12 1 13 -1 6 14 15 -1 6 12 14 -1 7 16 17 -1 7 17 18 -1 16 7 0 -1 16 0 19 -1 7 3 0 -1 4 3 7 -1 20 4 21 -1 22 4 20 -1 4 22 3 -1 3 22 23 -1 20 12 22 -1 12 20 14 -1 3 13 1 -1 13 3 23 -1 20 15 14 -1 15 20 21 -1 15 4 6 -1 4 15 21 -1 23 12 13 -1 12 23 22 -1 18 5 7 -1 5 18 11 -1 10 16 8 -1 16 10 17 -1 16 9 8 -1 9 16 19 -1 18 10 11 -1 10 18 17 -1 19 2 9 -1 2 19 0 -1 
                          ]
                          creaseAngle 1
                        }
                      }
                    ]
                  }
                  HingeJoint {
                    jointParameters HingeJointParameters {
                      axis 1.000000 0.000000 0.000000
                      anchor 0.000000 0.000000 0.000000
                      dampingConstant 0.0
                      staticFriction 0.0
                    }
                    device [
                      RotationalMotor {
                        name "rightfemur2rightfoot"
                      }
                      PositionSensor {
                        name "rightfemur2rightfoot_sensor"
                      }
                    ]
                    endPoint Solid {
                      translation 0.000000 0.000000 0.000000
                      rotation 1.000000 0.000000 0.000000 0.000000
                      children [
                        Transform {
                          translation 0.025000 -0.240000 0.000000
                          rotation 0.000000 1.000000 0.000000 0.000000
                          children [
                            Shape {
                              appearance PBRAppearance {
                                baseColor 1.000000 0.000000 0.000000
                                transparency 0.000000
                                roughness 1.000000
                                metalness 0
                                emissiveColor 0.000000 0.000000 0.000000
                              }
                              geometry DEF rightfoot2 IndexedFaceSet {
                                coord Coordinate {
                                  point [
                                    -0.040450 0.000000 0.029388, 0.015450 -0.049999 0.047552, 0.015450 0.000000 0.047552, -0.040450 -0.049999 0.029388, 0.049999 0.000000 0.000000, 0.049999 -0.049999 0.000000, -0.040450 -0.049999 0.000000, -0.040450 0.000000 0.000000, -0.049999 -0.049999 -0.030000, -0.049999 -0.049999 0.000000, 0.049999 -0.049999 -0.030000, 0.174999 0.000000 -0.049999, 0.049999 0.000000 -0.030000, 0.174999 0.000000 -0.030000, -0.049999 0.000000 -0.030000, -0.174999 0.000000 -0.049999, -0.174999 0.000000 -0.030000, -0.049999 0.000000 0.000000, 0.174999 -0.250000 -0.030000, 0.174999 -0.250000 -0.049999, -0.174999 -0.250000 -0.049999, -0.174999 -0.250000 -0.030000, 
                                  ]
                                }
                                coordIndex [
                                  1 0 3 -1 1 4 2 -1 4 1 5 -1 6 0 7 -1 0 6 3 -1 8 6 9 -1 10 6 8 -1 6 10 5 -1 6 1 3 -1 1 6 5 -1 11 12 13 -1 12 11 14 -1 15 14 11 -1 14 15 16 -1 7 2 4 -1 2 7 0 -1 12 7 4 -1 14 7 12 -1 7 14 17 -1 18 11 13 -1 11 18 19 -1 20 18 21 -1 18 20 19 -1 20 16 15 -1 16 20 21 -1 14 16 8 -1 10 13 12 -1 13 10 18 -1 8 18 10 -1 21 8 16 -1 8 21 18 -1 20 11 19 -1 11 20 15 -1 5 12 4 -1 12 5 10 -1 8 17 14 -1 17 8 9 -1 17 6 7 -1 6 17 9 -1 
                                ]
                                creaseAngle 1
                              }
                            }
                          ]
                        }
                      ]
                      name "rightfoot"
                      boundingObject Transform {
                        translation 0.025000 -0.240000 0.000000
                        rotation 0.000000 1.000000 0.000000 0.000000
                        children [
                          USE rightfoot2
                        ]
                      }
                      physics Physics {
                        density -1
                        mass 4.000000
                        centerOfMass [ 0.000000 0.000000 0.000000 ]
                      }
                    }
                  }
                ]
                name "rightfemur"
                boundingObject Transform {
                  translation 0.000000 -0.240000 0.000000
                  rotation 0.000000 1.000000 0.000000 0.000000
                  children [
                    USE rightfemur2
                  ]
                }
                physics Physics {
                  density -1
                  mass 4.000000
                  centerOfMass [ 0.000000 0.000000 0.000000 ]
                }
              }
            }
          ]
          name "rightthigh"
          boundingObject Transform {
            translation 0.000000 -0.190000 0.300000
            rotation 0.000000 1.000000 0.000000 0.000000
            children [
              USE rightthigh2
            ]
          }
          physics Physics {
            density -1
            mass 4.000000
            centerOfMass [ 0.000000 0.000000 0.000000 ]
          }
        }
      }
      HingeJoint {
        jointParameters HingeJointParameters {
          axis 1.000000 0.000000 0.000000
          anchor 0.000000 0.000000 0.000000
          dampingConstant 0.0
          staticFriction 0.0
        }
        device [
          RotationalMotor {
            name "hip2leftthigh"
          }
          PositionSensor {
            name "hip2leftthigh_sensor"
          }
        ]
        endPoint Solid {
          translation 0.000000 0.000000 0.000000
          rotation 1.000000 0.000000 0.000000 0.000000
          children [
            Transform {
              translation 0.000000 0.190000 0.300000
              rotation 0.000000 1.000000 0.000000 0.000000
              children [
                Shape {
                  appearance PBRAppearance {
                    baseColor 1.000000 0.000000 0.000000
                    transparency 0.000000
                    roughness 1.000000
                    metalness 0
                    emissiveColor 0.000000 0.000000 0.000000
                  }
                  geometry DEF leftthigh2 IndexedFaceSet {
                    coord Coordinate {
                      point [
                        0.049999 0.000000 0.265590, 0.049999 0.049999 0.034409, 0.049999 0.049999 0.265590, 0.049999 0.000000 0.034409, 0.000000 0.000000 0.034409, 0.000000 0.049999 0.265590, 0.000000 0.049999 0.034409, 0.000000 0.000000 0.265590, 0.040450 0.049999 0.347552, 0.075000 0.049999 0.299999, -0.015450 0.049999 0.329389, -0.015450 0.049999 0.270610, 0.040450 0.049999 -0.047552, 0.075000 0.049999 0.000000, -0.015450 0.049999 -0.029388, -0.015450 0.049999 0.029388, 0.040450 0.000000 0.347552, -0.015450 0.000000 0.329389, -0.015450 0.000000 0.270610, 0.075000 0.000000 0.299999, -0.015450 0.000000 -0.029388, -0.015450 0.000000 0.029388, 0.040450 0.000000 -0.047552, 0.075000 0.000000 0.000000, 
                      ]
                    }
                    coordIndex [
                      1 0 3 -1 4 5 6 -1 5 4 7 -1 2 8 9 -1 5 8 2 -1 8 5 10 -1 10 5 11 -1 1 5 2 -1 1 6 5 -1 12 6 1 -1 12 1 13 -1 6 14 15 -1 6 12 14 -1 7 16 17 -1 7 17 18 -1 16 7 0 -1 16 0 19 -1 7 3 0 -1 4 3 7 -1 20 4 21 -1 22 4 20 -1 4 22 3 -1 3 22 23 -1 20 12 22 -1 12 20 14 -1 3 13 1 -1 13 3 23 -1 20 15 14 -1 15 20 21 -1 15 4 6 -1 4 15 21 -1 23 12 13 -1 12 23 22 -1 18 5 7 -1 5 18 11 -1 16 9 8 -1 9 16 19 -1 18 10 11 -1 10 18 17 -1 19 2 9 -1 2 19 0 -1 10 16 8 -1 16 10 17 -1 
                    ]
                    creaseAngle 1
                  }
                }
              ]
            }
            HingeJoint {
              jointParameters HingeJointParameters {
                axis 1.000000 0.000000 0.000000
                anchor 0.000000 0.000000 0.000000
                dampingConstant 0.0
                staticFriction 0.0
              }
              device [
                RotationalMotor {
                  name "leftthigh2leftfemur"
                }
                PositionSensor {
                  name "leftthigh2leftfemur_sensor"
                }
              ]
              endPoint Solid {
                translation 0.000000 0.000000 0.000000
                rotation 1.000000 0.000000 0.000000 0.000000
                children [
                  Transform {
                    translation 0.000000 0.240000 0.000000
                    rotation 0.000000 1.000000 0.000000 0.000000
                    children [
                      Shape {
                        appearance PBRAppearance {
                          baseColor 1.000000 0.000000 0.000000
                          transparency 0.000000
                          roughness 1.000000
                          metalness 0
                          emissiveColor 0.000000 0.000000 0.000000
                        }
                        geometry DEF leftfemur2 IndexedFaceSet {
                          coord Coordinate {
                            point [
                              0.049999 0.000000 0.265590, 0.049999 0.049999 0.034409, 0.049999 0.049999 0.265590, 0.049999 0.000000 0.034409, 0.000000 0.000000 0.034409, 0.000000 0.049999 0.265590, 0.000000 0.049999 0.034409, 0.000000 0.000000 0.265590, 0.040450 0.049999 0.347552, 0.075000 0.049999 0.299999, -0.015450 0.049999 0.329389, -0.015450 0.049999 0.270610, 0.040450 0.049999 -0.047552, 0.075000 0.049999 0.000000, -0.015450 0.049999 -0.029388, -0.015450 0.049999 0.029388, 0.040450 0.000000 0.347552, -0.015450 0.000000 0.329389, -0.015450 0.000000 0.270610, 0.075000 0.000000 0.299999, -0.015450 0.000000 -0.029388, -0.015450 0.000000 0.029388, 0.040450 0.000000 -0.047552, 0.075000 0.000000 0.000000, 
                            ]
                          }
                          coordIndex [
                            1 0 3 -1 4 5 6 -1 5 4 7 -1 2 8 9 -1 5 8 2 -1 8 5 10 -1 10 5 11 -1 1 5 2 -1 1 6 5 -1 12 6 1 -1 12 1 13 -1 6 14 15 -1 6 12 14 -1 7 16 17 -1 7 17 18 -1 16 7 0 -1 16 0 19 -1 7 3 0 -1 4 3 7 -1 20 4 21 -1 22 4 20 -1 4 22 3 -1 3 22 23 -1 20 12 22 -1 12 20 14 -1 3 13 1 -1 13 3 23 -1 20 15 14 -1 15 20 21 -1 15 4 6 -1 4 15 21 -1 23 12 13 -1 12 23 22 -1 18 5 7 -1 5 18 11 -1 10 16 8 -1 16 10 17 -1 16 9 8 -1 9 16 19 -1 18 10 11 -1 10 18 17 -1 19 2 9 -1 2 19 0 -1 
                          ]
                          creaseAngle 1
                        }
                      }
                    ]
                  }
                  HingeJoint {
                    jointParameters HingeJointParameters {
                      axis 1.000000 0.000000 0.000000
                      anchor 0.000000 0.000000 0.000000
                      dampingConstant 0.0
                      staticFriction 0.0
                    }
                    device [
                      RotationalMotor {
                        name "leftfemur2leftfoot"
                      }
                      PositionSensor {
                        name "leftfemur2leftfoot_sensor"
                      }
                    ]
                    endPoint Solid {
                      translation 0.000000 0.000000 0.000000
                      rotation 1.000000 0.000000 0.000000 0.000000
                      children [
                        Transform {
                          translation 0.025000 0.340000 0.000000
                          rotation 0.000000 1.000000 0.000000 0.000000
                          children [
                            Shape {
                              appearance PBRAppearance {
                                baseColor 1.000000 0.000000 0.000000
                                transparency 0.000000
                                roughness 1.000000
                                metalness 0
                                emissiveColor 0.000000 0.000000 0.000000
                              }
                              geometry DEF leftfoot2 IndexedFaceSet {
                                coord Coordinate {
                                  point [
                                    -0.040450 0.000000 0.029388, 0.015450 -0.049999 0.047552, 0.015450 0.000000 0.047552, -0.040450 -0.049999 0.029388, 0.049999 0.000000 0.000000, 0.049999 -0.049999 0.000000, -0.040450 -0.049999 0.000000, -0.040450 0.000000 0.000000, -0.174999 -0.049999 -0.049999, -0.049999 -0.049999 -0.030000, -0.174999 -0.049999 -0.030000, 0.049999 -0.049999 -0.030000, 0.174999 -0.049999 -0.049999, 0.174999 -0.049999 -0.030000, -0.049999 -0.049999 0.000000, 0.049999 0.000000 -0.030000, -0.049999 0.000000 -0.030000, -0.049999 0.000000 0.000000, 0.174999 0.200000 -0.049999, 0.174999 0.200000 -0.030000, -0.174999 0.200000 -0.030000, -0.174999 0.200000 -0.049999, 
                                  ]
                                }
                                coordIndex [
                                  1 0 3 -1 1 4 2 -1 4 1 5 -1 6 0 7 -1 0 6 3 -1 8 9 10 -1 9 8 11 -1 12 11 8 -1 11 12 13 -1 9 6 14 -1 11 6 9 -1 6 11 5 -1 6 1 3 -1 1 6 5 -1 7 2 4 -1 2 7 0 -1 15 7 4 -1 16 7 15 -1 7 16 17 -1 13 18 19 -1 18 13 12 -1 18 20 19 -1 20 18 21 -1 8 20 21 -1 20 8 10 -1 19 15 13 -1 19 16 15 -1 20 16 19 -1 10 16 20 -1 16 10 9 -1 13 15 11 -1 8 18 12 -1 18 8 21 -1 5 15 4 -1 15 5 11 -1 9 17 16 -1 17 9 14 -1 17 6 7 -1 6 17 14 -1 
                                ]
                                creaseAngle 1
                              }
                            }
                          ]
                        }
                      ]
                      name "leftfoot"
                      boundingObject Transform {
                        translation 0.025000 0.340000 0.000000
                        rotation 0.000000 1.000000 0.000000 0.000000
                        children [
                          USE leftfoot2
                        ]
                      }
                      physics Physics {
                        density -1
                        mass 4.000000
                        centerOfMass [ 0.000000 0.000000 0.000000 ]
                      }
                    }
                  }
                ]
                name "leftfemur"
                boundingObject Transform {
                  translation 0.000000 0.240000 0.000000
                  rotation 0.000000 1.000000 0.000000 0.000000
                  children [
                    USE leftfemur2
                  ]
                }
                physics Physics {
                  density -1
                  mass 4.000000
                  centerOfMass [ 0.000000 0.000000 0.000000 ]
                }
              }
            }
          ]
          name "leftthigh"
          boundingObject Transform {
            translation 0.000000 0.190000 0.300000
            rotation 0.000000 1.000000 0.000000 0.000000
            children [
              USE leftthigh2
            ]
          }
          physics Physics {
            density -1
            mass 4.000000
            centerOfMass [ 0.000000 0.000000 0.000000 ]
          }
        }
      }
    ]
    name "hip"
    boundingObject Transform {
      translation 0.000000 -0.010000 0.000000
      rotation 0.000000 1.000000 0.000000 0.000000
      children [
        USE hip2
      ]
    }
    physics Physics {
      density -1
      mass 4.000000
      centerOfMass [ 0.000000 0.000000 0.000000 ]
    }
  }
}
